Workbook

Sheet 卡池总览
A1: 千秋策 · 朝代卡池总览
A2: 数值基准：《部署价值表》E3 ＋《基础公式》B20（含「策略卡：部署后产生的收益等于部署费用」）。本次未修改任何基准表单元格；两个卡池只使用《基础公式》B26:D64 里登记过的词条与效果，buff 类写进效果栏、按费率计价。
A4: 一、卡池规模与平衡偏差
B5: 总张数 | C5: 兵牌 | D5: 策略牌 | E5: 普通 | F5: 稀有 | G5: 史诗/传说
A6: 秦·赳赳老秦 | B6: 24 | C6: 17 | D6: 7 | E6: 8 | F6: 8 | G6: 5 / 3
A7: 汉·大汉雄风 | B7: 24 | C7: 18 | D7: 6 | E7: 8 | F7: 8 | G7: 5 / 3
A9: 校验项 | B9: 兵牌最差一类（按门槛归一化） | C9: 兵牌越界张数 | D9: 策略牌「Σ效果价 − 费用」最大偏差 | E9: 判定口径
A10: 秦表 | B10: 0.342（qin_011，门槛 0.35） | C10: 0 | D10: 0 | E10: 兵牌：|卡牌价值−部署价值|≤0.35（1费放宽到0.6）；策略牌：卡牌价值=部署费用，Σ效果价必须正好等于费用
A11: 汉表 | B11: 0.342（han_011，门槛 0.35） | C11: 0 | D11: 0 | E11: 兵牌：|卡牌价值−部署价值|≤0.35（1费放宽到0.6）；策略牌：卡牌价值=部署费用，Σ效果价必须正好等于费用
A13: 二、费用分布（策划案 §4.5 建议：1~2费 10~12 张 / 3~4费 12~14 张 / 5费+ 4~6 张）
B14: 1费 | C14: 2费 | D14: 3费 | E14: 4费 | F14: 5费 | G14: 6费+
A15: 秦 | B15: =COUNTIF(秦·卡池!$I$5:$I$200,1) -> 2 | C15: =COUNTIF(秦·卡池!$I$5:$I$200,2) -> 6 | D15: =COUNTIF(秦·卡池!$I$5:$I$200,3) -> 6 | E15: =COUNTIF(秦·卡池!$I$5:$I$200,4) -> 5 | F15: =COUNTIF(秦·卡池!$I$5:$I$200,5) -> 1 | G15: =COUNTIF(秦·卡池!$I$5:$I$200,">=6") -> 4
A16: 汉 | B16: =COUNTIF(汉·卡池!$I$5:$I$200,1) -> 2 | C16: =COUNTIF(汉·卡池!$I$5:$I$200,2) -> 3 | D16: =COUNTIF(汉·卡池!$I$5:$I$200,3) -> 8 | E16: =COUNTIF(汉·卡池!$I$5:$I$200,4) -> 5 | F16: =COUNTIF(汉·卡池!$I$5:$I$200,5) -> 3 | G16: =COUNTIF(汉·卡池!$I$5:$I$200,">=6") -> 3
A18: 秦策略牌费用 | B18: 1、2、2、2、4、4、6
A19: 汉策略牌费用 | B19: 1、2、3、4、4、5
A21: 三、本次相对旧《赳赳老秦》表的改动（旧表保留在原地未动，可对照）
A22: · 列结构：去掉「定位」列（对程序无用）；新增「行动费用」「射程」「keywords(程序)」列，与 CardData.cs 字段一一对齐；「词条等价」改名为「效果等价」（同时容纳词条价与效果价）。
A23: · 词条白名单：两个卡池只使用《基础公式》B26:D64 登记过的条目；原先自造的 誓师、临时ATK+3、指定直伤5、整排伤害3、攻击后大营回血2 等表外条目已全部拆除。
A24: · buff 类：不再作为独立词条，改写入「效果」栏，按基础表 B50/B51/B52 的费率计价（atk 0.75/点、hp 0.5/点、atk+hp 各 0.6/点），一次性增减数值、无持续时间。
A25: · 策略牌价值：按《基础公式》B20「策略卡：部署后产生的收益等于部署费用」，卡牌价值 V 直接等于部署费用 I——既不套兵牌的 β·atk+α·hp 公式，也不等于 Σ效果价。因此策略卡一行写的是「部署价值 = 卡牌价值 = 部署费用」；W 列的负值只是 cost_value 把费用换算成面板的参考值，对策略卡没有意义。Σ效果价 是配平时的硬约束：必须恰等于费用。
A26: · 策略卡不再带词条：抽牌/回血/直伤/压制/弃牌/等价类/召唤/buff 全部是「效果」，keywords 列留空。
A27: · 汉·汉家大黄弩（部署召唤，词条列写「召唤(牌堆)」）。
A28: · 兵牌效果栏：除两张支援卡（秦·连弩台、汉·治粟都尉，按 B50「仅限策略卡和支援卡的部署效果」写 buff）外，其余兵牌的增益一律做成词条（守护/血战/连战/重甲/闪击/伏兵/召唤），不带效果、效果价 0。
A29: · 闪击：按你确认只对骑兵适用（骑兵携带=0 / 骑兵未携带 −0.5），步/弓/器不受该条影响。
A30: · 血战按基础表 1.5（不是策划案的 2.0）；守护携带者部署时 +1HP 已含在卡面 HP 里。
A31: · 行动费用按策划案 §2.5 档位表（步兵轻中=1/重=2；骑兵轻=1/中重=2；弓兵轻中=1/重=2；器械=2）。行动次数：骑兵为 2、携带连战者为 2、其余一律为 1——器械每回合只能攻击一次。行动次数只影响每回合能打几下，不进入部署价值公式（部署价值只取部署费用 dcs 与行动费用 acs）。射程：弓兵与器械为 2、其余为 1。
A32: · 支援(器械)类：本次两表各 1 张（秦·连弩台、汉·治粟都尉，3 费·重·3/4·2acs·2AP·射程2）——按你更新后的 E12:F12 = 1/1 系数、且行动次数 = 1（每回合一次攻击）重做；旧系数 2/2 时该类别无法成立，详见《基准表外条目》「三、」。
A33: · 「效果等价」列由脚本算好后写死（不参与 Excel 重算）；「部署价值 / 卡牌价值 / 差值」是活公式，改 I/J/L/M 会自动重算，改了 O 列词条或效果栏后重跑 build_dynasty_sheets.py 让「效果等价」列同步。

Sheet 基础公式
E6: 系数 | F6: 系数
C7: Deployment costs | D7: Action cost | E7: atk | F7: hp | G7: Entry1 | H7: Entry2 | I7: Entry3 | J7: Entry4 | K7: value
C8: 部署费用 | D8: 行动费用 | E8: 攻击力 | F8: 生命值 | G8: 词条1 | H8: 词条2 | I8: 词条3 | J8: 词条4 | K8: 价值
B9: 步兵类 | E9: 1.1 | F9: 0.9 | G9: 0 | H9: 0 | I9: 0 | J9: 0
B10: 骑兵类 | E10: 0.9 | F10: 1.1 | G10: 0 | H10: 0 | I10: 0 | J10: 0
B11: 弓兵类 | E11: 1.2 | F11: 0.8 | G11: 0 | H11: 0 | I11: 0 | J11: 0
B12: 支援类 | E12: 1 | F12: 1 | G12: 0 | H12: 0 | I12: 0 | J12: 0
B13: 策略卡
B15: 通用公式 | C15: dcs | D15: acs
B17: 部署价值：cost_value = （3 - dcs/8) * dcs + 2 * acs / 3 - 1
B20: 策略卡：部署后产生的收益等于部署费用
B23: 卡牌价值：card_value = β * atk + α * hp + Σentry
B26: 词条 | C26: 效果 | D26: 等价费用 | E26: 备注
B27: 闪击 | C27: 部署回合可移动或攻击 | D27: 0.5 | E27: 骑兵类携带时等价为0，未携带算入-0.5
B28: 伏兵 | C28: 在主动攻击前不可被攻击 | D28: 0.5
B29: 守护 | C29: 单位存活时，同排相邻槽位的友方单位与建筑不能被选中（守护单位之间不互相保护） | D29: 1 | E29: 带有该词条的单位，部署时+1hp
B30: 血战 | C30: 攻击后回复2hp | D30: 1.5
B31: 连战 | C31: 同一回合可连续攻击两次 | D31: 1 | E31: 两次攻击独立计算
B32: 摸牌类 | C32: 抽取1张牌 | D32: 1 | E32: 仅限策略卡
C33: 抽取2张牌 | D33: 3
C34: 抽取3张牌 | D34: 6
B35: 召唤类 | C35: 部署时添加一张卡牌进入牌堆 | D35: 0.5 | E35: 创建一张卡牌进入牌堆，不管是否携带
C36: 部署时将一张卡从牌堆加入手牌 | D36: 1 | E36: 牌堆中必须有这张牌，没有不生效
B37: 加血类 | C37: 为建筑回复3hp | D37: 1 | E37: 仅限策略卡
C38: 为建筑回复5hp | D38: 2
C39: 为建筑回复7hp | D39: 3
C40: 为兵回复3hp | D40: 2
C41: 攻击后，为大营回复2hp | D41: 1.5 | E41: 仅限兵种卡
B42: 重甲1 | C42: 每层重甲在受到伤害时减少一点 | D42: 1 | E42: 仅重型单位可携带
B43: 重甲2 | C43: 每层重甲在受到伤害时减少一点 | D43: 2.5
B44: 重甲3 | C44: 每层重甲在受到伤害时减少一点 | D44: 4
B45: 反制 | E45: 满足触发条件时自动使用，不可主动使用，不消耗费用，起解场作用
B48: 压制 | C48: 限制敌方单位一回合行动 | D48: 1 | E48: 仅策略卡，仅可作用于兵牌
B49: 抵抗 | C49: 免疫压制效果 | D49: 0.5 | E49: 仅兵牌，重甲3以0费附带该词条
B50: buff类 | C50: 增加atk | D50: 每点atk记0.75费 | E50: 仅限策略卡和支援卡的部署效果，增加数值的费用不得超过3费
C51: 增加hp | D51: 每点hp记0.5费
C52: 增加atk和hp | D52: 每点atk和hp均记0.6费
B53: 等价类 | C53: 将指定单位的atk调整到与hp相同 | D53: 3 | E53: 固定3费策略卡
C54: 将对方任意单位的hp调整到1 | D54: 2 | E54: 固定2费策略卡
C55: 将对方任意单位的atk调整到1 | D55: 2 | E55: 固定2费策略卡
...

Sheet 部署价值表
E3: cost_value = （3 - dcs/8) * dcs + 2 * acs / 3 - 1
B7: acs\dcs | C7: 1 | D7: 2 | E7: 3 | F7: 4 | G7: 5 | H7: 6 | I7: 7 | J7: 8 | K7: 9 | L7: 10 | M7: 11 | N7: 12
B8: 0 | C8: =(3-C$7/8)*C$7+2*$B8/3-1 -> 1.875 | D8: =(3-D$7/8)*D$7+2*$B8/3-1 -> 4.5 | E8: =(3-E$7/8)*E$7+2*$B8/3-1 -> 6.875 | F8: =(3-F$7/8)*F$7+2*$B8/3-1 -> 9 | G8: =(3-G$7/8)*G$7+2*$B8/3-1 -> 10.875 | H8: =(3-H$7/8)*H$7+2*$B8/3-1 -> 12.5 | I8: =(3-I$7/8)*I$7+2*$B8/3-1 -> 13.875 | J8: =(3-J$7/8)*J$7+2*$B8/3-1 -> 15 | ... N8: =(3-N$7/8)*N$7+2*$B8/3-1 -> 17
B9: 1 | C9: =(3-C$7/8)*C$7+2*$B9/3-1 -> 2.5416667 | D9: =(3-D$7/8)*D$7+2*$B9/3-1 -> 5.1666667 | E9: =(3-E$7/8)*E$7+2*$B9/3-1 -> 7.5416667 | F9: =(3-F$7/8)*F$7+2*$B9/3-1 -> 9.6666667 | G9: =(3-G$7/8)*G$7+2*$B9/3-1 -> 11.541667 | H9: =(3-H$7/8)*H$7+2*$B9/3-1 -> 13.166667 | I9: =(3-I$7/8)*I$7+2*$B9/3-1 -> 14.541667 | J9: =(3-J$7/8)*J$7+2*$B9/3-1 -> 15.666667 | ... N9: =(3-N$7/8)*N$7+2*$B9/3-1 -> 17.666667
B10: 2 | C10: =(3-C$7/8)*C$7+2*$B10/3-1 -> 3.2083333 | D10: =(3-D$7/8)*D$7+2*$B10/3-1 -> 5.8333333 | E10: =(3-E$7/8)*E$7+2*$B10/3-1 -> 8.2083333 | F10: =(3-F$7/8)*F$7+2*$B10/3-1 -> 10.333333 | G10: =(3-G$7/8)*G$7+2*$B10/3-1 -> 12.208333 | H10: =(3-H$7/8)*H$7+2*$B10/3-1 -> 13.833333 | I10: =(3-I$7/8)*I$7+2*$B10/3-1 -> 15.208333 | J10: =(3-J$7/8)*J$7+2*$B10/3-1 -> 16.333333 | ... N10: =(3-N$7/8)*N$7+2*$B10/3-1 -> 18.333333
B11: 3 | C11: =(3-C$7/8)*C$7+2*$B11/3-1 -> 3.875 | D11: =(3-D$7/8)*D$7+2*$B11/3-1 -> 6.5 | E11: =(3-E$7/8)*E$7+2*$B11/3-1 -> 8.875 | F11: =(3-F$7/8)*F$7+2*$B11/3-1 -> 11 | G11: =(3-G$7/8)*G$7+2*$B11/3-1 -> 12.875 | H11: =(3-H$7/8)*H$7+2*$B11/3-1 -> 14.5 | I11: =(3-I$7/8)*I$7+2*$B11/3-1 -> 15.875 | J11: =(3-J$7/8)*J$7+2*$B11/3-1 -> 17 | ... N11: =(3-N$7/8)*N$7+2*$B11/3-1 -> 19

Sheet 秦·卡池
A1: 秦朝卡池 · 赳赳老秦（按新列结构重建）
A2: 数值基准：《部署价值表》E3 cost_value=(3-dcs/8)*dcs+2*acs/3-1 ；《基础公式》B20 card_value=β*atk+α*hp+Σ词条等价费用。策略牌按 B20 后半句「部署后产生的收益等于部署费用」，卡牌价值直接等于部署费用。本表不修改任何基准表单元格。
A4: 一、兵种系数表（引用《基础公式》E9:F12）
A5: cardType / unitType | B5: β（ATK） | C5: α（HP）
A6: 步兵 | B6: =基础公式!E9 -> 1.1 | C6: =基础公式!F9 -> 0.9
A7: 骑兵 | B7: =基础公式!E10 -> 0.9 | C7: =基础公式!F10 -> 1.1
A8: 弓兵 | B8: =基础公式!E11 -> 1.2 | C8: =基础公式!F11 -> 0.8
A9: 支援 | B9: =基础公式!E12 -> 1 | C9: =基础公式!F12 -> 1
A11: 二、词条/效果等价费用表（逐条抄录《基础公式》B26:D64；本表不含任何基准表以外的条目）
A12: 词条/效果 | B12: 等价费用 | C12: 来源/口径
A13: 闪击 | B13: 0.5 | C13: B27｜部署回合可移动或攻击。按兵种特例：骑兵携带=0，骑兵未携带=-0.5；步/弓/器不受该条影响（本次锁定）
A14: 伏兵 | B14: 0.5 | C14: B28｜在主动攻击前不可被攻击
A15: 守护 | B15: 1 | C15: B29｜单位存活时，同排相邻槽位的友方单位与建筑不能被选中；携带者部署时+1HP（E26），卡面HP已含
A16: 血战 | B16: 1.5 | C16: B30｜攻击后回复2HP（被反击不回）；数值以基础表为准（1.5）
A17: 连战 | B17: 1 | C17: B31｜同一回合可连续攻击两次，行动次数按2计
A18: 摸牌1 | B18: 1 | C18: B32｜抽取1张牌
A19: 摸牌2 | B19: 3 | C19: B33｜抽取2张牌
A20: 摸牌3 | B20: 6 | C20: B34｜抽取3张牌
A21: 召唤(牌堆) | B21: 0.5 | C21: B35｜部署时添加一张卡牌进入牌堆
A22: 召唤(手牌) | B22: 1 | C22: B36｜部署时将一张卡从牌堆加入手牌
A23: 建筑回血3 | B23: 1 | C23: B37｜为建筑回复3hp
A24: 建筑回血5 | B24: 2 | C24: B38｜为建筑回复5hp
... A44: buff·增加atk和hp | B44: 0.6 | C44: B52｜每点 atk 和 hp 均记 0.6 费
A45: buff 类用法 | B45: — | C45: buff 不是独立词条：写进「效果」栏，一次性增减数值、不设持续时间，不占 keywords 列
A47: 三、秦卡池（24 张）—— 列名与 CardData.cs 字段对齐；「效果等价」列为脚本算好的等价费用（不参与 Excel 重算，改词条/效果后重跑生成脚本），「部署价值 / 卡牌价值 / 差值」为活公式，改 I/J/L/M 会自动重算
A48: 序号 | B48: cardId | C48: 名称 | D48: 朝代 | E48: 稀有度 | F48: cardType | G48: unitType | H48: 重量 | I48: 部署费用 | J48: 行动费用 | K48: 行动次数 | L48: ATK | M48: HP | N48: 射程 | O48: keywords | P48: keywords(程序) | Q48: 效果 | R48: 古文描述 | S48: 出处 | T48: 效果等价 | U48: 部署价值 | V48: 卡牌价值 | W48: 差值
A49: 1 | B49: qin_001 | C49: 什伍卒 | D49: 秦 | E49: 普通 | F49: 兵牌 | G49: 步兵 | H49: 轻 | I49: 1 | J49: 1 | K49: 1 | L49: 1 | M49: 2 | N49: 1 | R49: 令民为什伍，而相牧司连坐。 | S49: 《史记·商君列传》 | T49: 0 | U49: =ROUND((3-$I49/8)*$I49+2*$J49/3-1,3) -> 2.542 | V49: =IF($F49="策略牌",$I49,ROUND(VLOOKUP($G49,$A$6:$C$9,2,FALSE)*N($L49)+VLOOKUP($G49,$A$6:$C$9,3,FALSE)*N($M49)+$T49,3)) -> 2.9 | W49: =ROUND($V49-$U49,3) -> 0.358
A50: 2 | B50: qin_002 | C50: 戍卒 | D50: 秦 | E50: 普通 | F50: 兵牌 | G50: 步兵 | H50: 中 | I50: 2 | J50: 1 | K50: 1 | L50: 2 | M50: 3 | N50: 1 | R50: 发闾左適戍渔阳九百人，屯大泽乡。 | S50: 《史记·陈涉世家》 | T50: 0 | U50: =ROUND((3-$I50/8)*$I50+2*$J50/3-1,3) -> 5.167 | V50: =IF($F50="策略牌",$I50,ROUND(VLOOKUP($G50,$A$6:$C$9,2,FALSE)*N($L50)+VLOOKUP($G50,$A$6:$C$9,3,FALSE)*N($M50)+$T50,3)) -> 4.9 | W50: =ROUND($V50-$U50,3) -> -0.267
A51: 3 | B51: qin_003 | C51: 秦锐士 | D51: 秦 | E51: 普通 | F51: 兵牌 | G51: 步兵 | H51: 中 | I51: 3 | J51: 1 | K51: 1 | L51: 3 | M51: 5 | N51: 1 | R51: 魏氏之武卒，不可以遇秦之锐士。 | S51: 《荀子·议兵》 | T51: 0 | U51: =ROUND((3-$I51/8)*$I51+2*$J51/3-1,3) -> 7.542 | V51: =IF($F51="策略牌",$I51,ROUND(VLOOKUP($G51,$A$6:$C$9,2,FALSE)*N($L51)+VLOOKUP($G51,$A$6:$C$9,3,FALSE)*N($M51)+$T51,3)) -> 7.8 | W51: =ROUND($V51-$U51,3) -> 0.258
A52: 4 | B52: qin_004 | C52: 劲弩手 | D52: 秦 | E52: 普通 | F52: 兵牌 | G52: 弓兵 | H52: 轻 | I52: 2 | J52: 1 | K52: 1 | L52: 3 | M52: 2 | N52: 2 | R52: 秦带甲百余万，车千乘，骑万匹。 | S52: 《史记·张仪列传》 | T52: 0 | U52: =ROUND((3-$I52/8)*$I52+2*$J52/3-1,3) -> 5.167 | V52: =IF($F52="策略牌",$I52,ROUND(VLOOKUP($G52,$A$6:$C$9,2,FALSE)*N($L52)+VLOOKUP($G52,$A$6:$C$9,3,FALSE)*N($M52)+$T52,3)) -> 5.2 | W52: =ROUND($V52-$U52,3) -> 0.033
A53: 5 | B53: qin_005 | C53: 连弩台 | D53: 秦 | E53: 普通 | F53: 兵牌 | G53: 支援 | H53: 重 | I53: 3 | J53: 2 | K53: 1 | L53: 3 | M53: 4 | N53: 2 | Q53: 部署当回合，指定一个友方单位本回合HP+3 | R53: 备高临以连弩之车；鼓之舞之，三军奋击。 | S53: 《墨子·备高临》(化用) | T53: 1.5 | U53: =ROUND((3-$I53/8)*$I53+2*$J53/3-1,3) -> 8.208 | V53: =IF($F53="策略牌",$I53,ROUND(VLOOKUP($G53,$A$6:$C$9,2,FALSE)*N($L53)+VLOOKUP($G53,$A$6:$C$9,3,FALSE)*N($M53)+$T53,3)) -> 8.5 | W53: =ROUND($V53-$U53,3) -> 0.292
A54: 6 | B54: qin_006 | C54: 疾驰轻骑 | D54: 秦 | E54: 普通 | F54: 兵牌 | G54: 骑兵 | H54: 轻 | I54: 2 | J54: 1 | K54: 2 | L54: 2 | M54: 3 | N54: 1 | O54: 闪击 | P54: Blitz | R54: 车骑之精，轻驰如风，掠野奔袭。 | S54: 《孙膑兵法·八阵》(化用) | T54: 0 | U54: =ROUND((3-$I54/8)*$I54+2*$J54/3-1,3) -> 5.167 | V54: =IF($F54="策略牌",$I54,ROUND(VLOOKUP($G54,$A$6:$C$9,2,FALSE)*N($L54)+VLOOKUP($G54,$A$6:$C$9,3,FALSE)*N($M54)+$T54,3)) -> 5.1 | W54: =ROUND($V54-$U54,3) -> -0.067
A55: 7 | B55: qin_007 | C55: 弩矢督 | D55: 秦 | E55: 普通 | F55: 策略牌 | G55: — | H55: — | I55: 1 | J55: 0 | Q55: 对敌方随机单位造成3点伤害 | R55: 矢石之积，皆入于仓，以时给之。 | S55: 睡虎地秦墓竹简·仓律(化用) | T55: 1 | U55: =ROUND((3-$I55/8)*$I55+2*$J55/3-1,3) -> 1.875 | V55: =IF($F55="策略牌",$I55,ROUND(VLOOKUP($G55,$A$6:$C$9,2,FALSE)*N($L55)+VLOOKUP($G55,$A$6:$C$9,3,FALSE)*N($M55)+$T55,3)) -> 1 | W55: =ROUND($V55-$U55,3) -> -0.875
A56: 8 | B56: qin_008 | C56: 攒射 | D56: 秦 | E56: 普通 | F56: 策略牌 | G56: — | H56: — | I56: 2 | J56: 0 | Q56: 对一名敌方兵牌造成3点伤害 | R56: 劲弩攒发，矢如飞蝗。 | S56: 《墨子·备城门》(化用) | T56: 2 | U56: =ROUND((3-$I56/8)*$I56+2*$J56/3-1,3) -> 4.5 | V56: =IF($F56="策略牌",$I56,ROUND(VLOOKUP($G56,$A$6:$C$9,2,FALSE)*N($L56)+VLOOKUP($G56,$A$6:$C$9,3,FALSE)*N($M56)+$T56,3)) -> 2 | W56: =ROUND($V56-$U56,3) -> -2.5
A57: 9 | B57: qin_009 | C57: 斥候骑 | D57: 秦 | E57: 稀有 | F57: 兵牌 | G57: 骑兵 | H57: 轻 | I57: 3 | J57: 1 | K57: 2 | L57: 3 | M57: 4 | N57: 1 | O57: 闪击,伏兵 | P57: Blitz,Ambush | R57: 斥候远窥，昼伏夜驰，以探敌情。 | S57: 《武经总要》(化用) | T57: 0.5 | U57: =ROUND((3-$I57/8)*$I57+2*$J57/3-1,3) -> 7.542 | V57: =IF($F57="策略牌",$I57,ROUND(VLOOKUP($G57,$A$6:$C$9,2,FALSE)*N($L57)+VLOOKUP($G57,$A$6:$C$9,3,FALSE)*N($M57)+$T57,3)) -> 7.6 | W57: =ROUND($V57-$U57,3) -> 0.058
A58: 10 | B58: qin_010 | C58: 轻车 | D58: 秦 | E58: 稀有 | F58: 兵牌 | G58: 骑兵 | H58: 中 | I58: 3 | J58: 2 | K58: 2 | L58: 3 | M58: 4 | N58: 1 | O58: 闪击,连战 | P58: Blitz,DoubleStrike | R58: 小戎俴收，五楘梁辀。 | S58: 《诗经·秦风·小戎》 | T58: 1 | U58: =ROUND((3-$I58/8)*$I58+2*$J58/3-1,3) -> 8.208 | V58: =IF($F58="策略牌",$I58,ROUND(VLOOKUP($G58,$A$6:$C$9,2,FALSE)*N($L58)+VLOOKUP($G58,$A$6:$C$9,3,FALSE)*N($M58)+$T58,3)) -> 8.1 | W58: =ROUND($V58-$U58,3) -> -0.108
A59: 11 | B59: qin_011 | C59: 穿杨弩手 | D59: 秦 | E59: 稀有 | F59: 兵牌 | G59: 弓兵 | H59: 中 | I59: 3 | J59: 1 | K59: 1 | L59: 4 | M59: 3 | N59: 2 | R59: 去柳叶百步而射之，百发百中。 | S59: 《战国策·西周策》(化用) | T59: 0 | U59: =ROUND((3-$I59/8)*$I59+2*$J59/3-1,3) -> 7.542 | V59: =IF($F59="策略牌",$I59,ROUND(VLOOKUP($G59,$A$6:$C$9,2,FALSE)*N($L59)+VLOOKUP($G59,$A$6:$C$9,3,FALSE)*N($M59)+$T59,3)) -> 7.2 | W59: =ROUND($V59-$U59,3) -> -0.342
A60: 12 | B60: qin_012 | C60: 铁鹰剑士 | D60: 秦 | E60: 稀有 | F60: 兵牌 | G60: 步兵 | H60: 重 | I60: 4 | J60: 2 | K60: 1 | L60: 5 | M60: 4 | N60: 1 | O60: 重甲1 | P60: HeavyArmor | R60: 王于兴师，修我甲兵，与子偕行。 | S60: 《诗经·秦风·无衣》 | T60: 1 | U60: =ROUND((3-$I60/8)*$I60+2*$J60/3-1,3) -> 10.333 | V60: =IF($F60="策略牌",$I60,ROUND(VLOOKUP($G60,$A$6:$C$9,2,FALSE)*N($L60)+VLOOKUP($G60,$A$6:$C$9,3,FALSE)*N($M60)+$T60,3)) -> 10.1 | W60: =ROUND($V60-$U60,3) -> -0.233
A61: 13 | B61: qin_013 | C61: 陷阵士 | D61: 秦 | E61: 稀有 | F61: 兵牌 | G61: 步兵 | H61: 中 | I61: 4 | J61: 1 | K61: 1 | L61: 4 | M61: 4 | N61: 1 | O61: 血战 | P61: BloodBattle | R61: 选锐冲之，分兵继之，急击勿疑。 | S61: 《吴子·料敌》 | T61: 1.5 | U61: =ROUND((3-$I61/8)*$I61+2*$J61/3-1,3) -> 9.667 | V61: =IF($F61="策略牌",$I61,ROUND(VLOOKUP($G61,$A$6:$C$9,2,FALSE)*N($L61)+VLOOKUP($G61,$A$6:$C$9,3,FALSE)*N($M61)+$T61,3)) -> 9.5 | W61: =ROUND($V61-$U61,3) -> -0.167
A62: 14 | B62: qin_014 | C62: 飞羽轻骑 | D62: 秦 | E62: 稀有 | F62: 兵牌 | G62: 骑兵 | H62: 轻 | I62: 4 | J62: 1 | K62: 2 | L62: 6 | M62: 4 | N62: 1 | O62: 闪击 | P62: Blitz | R62: 追亡逐北，伏尸百万，流血漂橹。 | S62: 贾谊《过秦论》(化用) | T62: 0 | U62: =ROUND((3-$I62/8)*$I62+2*$J62/3-1,3) -> 9.667 | V62: =IF($F62="策略牌",$I62,ROUND(VLOOKUP($G62,$A$6:$C$9,2,FALSE)*N($L62)+VLOOKUP($G62,$A$6:$C$9,3,FALSE)*N($M62)+$T62,3)) -> 9.8 | W62: =ROUND($V62-$U62,3) -> 0.133
...

Sheet 汉·卡池
A1: 汉朝卡池 · 大汉雄风（新建）
A2: 数值基准：《部署价值表》E3 cost_value=(3-dcs/8)*dcs+2*acs/3-1 ；《基础公式》B20 card_value=β*atk+α*hp+Σ词条等价费用。策略牌按 B20 后半句「部署后产生的收益等于部署费用」，卡牌价值直接等于部署费用。本表不修改任何基准表单元格。
A4: 一、兵种系数表（引用《基础公式》E9:F12）
A5: cardType / unitType | B5: β（ATK） | C5: α（HP）
A6: 步兵 | B6: =基础公式!E9 -> 1.1 | C6: =基础公式!F9 -> 0.9
A7: 骑兵 | B7: =基础公式!E10 -> 0.9 | C7: =基础公式!F10 -> 1.1
A8: 弓兵 | B8: =基础公式!E11 -> 1.2 | C8: =基础公式!F11 -> 0.8
A9: 支援 | B9: =基础公式!E12 -> 1 | C9: =基础公式!F12 -> 1
A11: 二、词条/效果等价费用表（逐条抄录《基础公式》B26:D64；本表不含任何基准表以外的条目）
A12: 词条/效果 | B12: 等价费用 | C12: 来源/口径
A13: 闪击 | B13: 0.5 | C13: B27｜部署回合可移动或攻击。按兵种特例：骑兵携带=0，骑兵未携带=-0.5；步/弓/器不受该条影响（本次锁定）
A14: 伏兵 | B14: 0.5 | C14: B28｜在主动攻击前不可被攻击
A15: 守护 | B15: 1 | C15: B29｜单位存活时，同排相邻槽位的友方单位与建筑不能被选中；携带者部署时+1HP（E26），卡面HP已含
A16: 血战 | B16: 1.5 | C16: B30｜攻击后回复2HP（被反击不回）；数值以基础表为准（1.5）
A17: 连战 | B17: 1 | C17: B31｜同一回合可连续攻击两次，行动次数按2计
A18: 摸牌1 | B18: 1 | C18: B32｜抽取1张牌
A19: 摸牌2 | B19: 3 | C19: B33｜抽取2张牌
A20: 摸牌3 | B20: 6 | C20: B34｜抽取3张牌
A21: 召唤(牌堆) | B21: 0.5 | C21: B35｜部署时添加一张卡牌进入牌堆
A22: 召唤(手牌) | B22: 1 | C22: B36｜部署时将一张卡从牌堆加入手牌
A23: 建筑回血3 | B23: 1 | C23: B37｜为建筑回复3hp
A24: 建筑回血5 | B24: 2 | C24: B38｜为建筑回复5hp
... A44: buff·增加atk和hp | B44: 0.6 | C44: B52｜每点 atk 和 hp 均记 0.6 费
A45: buff 类用法 | B45: — | C45: buff 不是独立词条：写进「效果」栏，一次性增减数值、不设持续时间，不占 keywords 列
A47: 三、汉卡池（24 张）—— 列名与 CardData.cs 字段对齐；「效果等价」列为脚本算好的等价费用（不参与 Excel 重算，改词条/效果后重跑生成脚本），「部署价值 / 卡牌价值 / 差值」为活公式，改 I/J/L/M 会自动重算
A48: 序号 | B48: cardId | C48: 名称 | D48: 朝代 | E48: 稀有度 | F48: cardType | G48: unitType | H48: 重量 | I48: 部署费用 | J48: 行动费用 | K48: 行动次数 | L48: ATK | M48: HP | N48: 射程 | O48: keywords | P48: keywords(程序) | Q48: 效果 | R48: 古文描述 | S48: 出处 | T48: 效果等价 | U48: 部署价值 | V48: 卡牌价值 | W48: 差值
A49: 1 | B49: han_001 | C49: 汉弩手 | D49: 汉 | E49: 普通 | F49: 兵牌 | G49: 弓兵 | H49: 轻 | I49: 2 | J49: 1 | K49: 1 | L49: 3 | M49: 2 | N49: 2 | R49: 汉弩一石十二斤，射程六百步。 | S49: 《汉书·匈奴传》(化用) | T49: 0 | U49: =ROUND((3-$I49/8)*$I49+2*$J49/3-1,3) -> 5.167 | V49: =IF($F49="策略牌",$I49,ROUND(VLOOKUP($G49,$A$6:$C$9,2,FALSE)*N($L49)+VLOOKUP($G49,$A$6:$C$9,3,FALSE)*N($M49)+$T49,3)) -> 5.2 | W49: =ROUND($V49-$U49,3) -> 0.033
A50: 2 | B50: han_002 | C50: 材官骑士 | D50: 汉 | E50: 普通 | F50: 兵牌 | G50: 骑兵 | H50: 轻 | I50: 1 | J50: 1 | K50: 2 | L50: 2 | M50: 1 | N50: 1 | O50: 闪击 | P50: Blitz | R50: 一岁为卫士，一岁为材官骑士。 | S50: 《汉书·食货志》 | T50: 0 | U50: =ROUND((3-$I50/8)*$I50+2*$J50/3-1,3) -> 2.542 | V50: =IF($F50="策略牌",$I50,ROUND(VLOOKUP($G50,$A$6:$C$9,2,FALSE)*N($L50)+VLOOKUP($G50,$A$6:$C$9,3,FALSE)*N($M50)+$T50,3)) -> 2.9 | W50: =ROUND($V50-$U50,3) -> 0.358
A51: 3 | B51: han_003 | C51: 边郡戍卒 | D51: 汉 | E51: 普通 | F51: 兵牌 | G51: 步兵 | H51: 中 | I51: 2 | J51: 1 | K51: 1 | L51: 2 | M51: 3 | N51: 1 | R51: 烽火通于甘泉、长安。 | S51: 《汉书·匈奴传》 | T51: 0 | U51: =ROUND((3-$I51/8)*$I51+2*$J51/3-1,3) -> 5.167 | V51: =IF($F51="策略牌",$I51,ROUND(VLOOKUP($G51,$A$6:$C$9,2,FALSE)*N($L51)+VLOOKUP($G51,$A$6:$C$9,3,FALSE)*N($M51)+$T51,3)) -> 4.9 | W51: =ROUND($V51-$U51,3) -> -0.267
A52: 4 | B52: han_004 | C52: 材官 | D52: 汉 | E52: 普通 | F52: 兵牌 | G52: 步兵 | H52: 中 | I52: 3 | J52: 1 | K52: 1 | L52: 3 | M52: 5 | N52: 1 | R52: 材官、骑士，各有员数。 | S52: 《汉书·高帝纪》 | T52: 0 | U52: =ROUND((3-$I52/8)*$I52+2*$J52/3-1,3) -> 7.542 | V52: =IF($F52="策略牌",$I52,ROUND(VLOOKUP($G52,$A$6:$C$9,2,FALSE)*N($L52)+VLOOKUP($G52,$A$6:$C$9,3,FALSE)*N($M52)+$T52,3)) -> 7.8 | W52: =ROUND($V52-$U52,3) -> 0.258
A53: 5 | B53: han_005 | C53: 治粟都尉 | D53: 汉 | E53: 普通 | F53: 兵牌 | G53: 支援 | H53: 重 | I53: 3 | J53: 2 | K53: 1 | L53: 3 | M53: 4 | N53: 2 | Q53: 部署当回合，指定一个友方单位本回合HP+3 | R53: 桑弘羊为治粟都尉，领大农，尽代仅斡天下盐铁。 | S53: 《史记·平准书》(化用) | T53: 1.5 | U53: =ROUND((3-$I53/8)*$I53+2*$J53/3-1,3) -> 8.208 | V53: =IF($F53="策略牌",$I53,ROUND(VLOOKUP($G53,$A$6:$C$9,2,FALSE)*N($L53)+VLOOKUP($G53,$A$6:$C$9,3,FALSE)*N($M53)+$T53,3)) -> 8.5 | W53: =ROUND($V53-$U53,3) -> 0.292
A54: 6 | B54: han_006 | C54: 游徼骑 | D54: 汉 | E54: 普通 | F54: 兵牌 | G54: 骑兵 | H54: 中 | I54: 3 | J54: 2 | K54: 2 | L54: 3 | M54: 4 | N54: 1 | O54: 闪击,连战 | P54: Blitz,DoubleStrike | R54: 繇役轻骑，往来如风。 | S54: 《汉书》(化用) | T54: 1 | U54: =ROUND((3-$I54/8)*$I54+2*$J54/3-1,3) -> 8.208 | V54: =IF($F54="策略牌",$I54,ROUND(VLOOKUP($G54,$A$6:$C$9,2,FALSE)*N($L54)+VLOOKUP($G54,$A$6:$C$9,3,FALSE)*N($M54)+$T54,3)) -> 8.1 | W54: =ROUND($V54-$U54,3) -> -0.108
A55: 7 | B55: han_007 | C55: 招降 | D55: 汉 | E55: 普通 | F55: 策略牌 | G55: — | H55: — | I55: 1 | J55: 0 | Q55: 对敌方随机单位造成3点伤害 | R55: 招降纳叛，来者不拒。 | S55: 《汉书》(化用) | T55: 1 | U55: =ROUND((3-$I55/8)*$I55+2*$J55/3-1,3) -> 1.875 | V55: =IF($F55="策略牌",$I55,ROUND(VLOOKUP($G55,$A$6:$C$9,2,FALSE)*N($L55)+VLOOKUP($G55,$A$6:$C$9,3,FALSE)*N($M55)+$T55,3)) -> 1 | W55: =ROUND($V55-$U55,3) -> -0.875
A56: 8 | B56: han_008 | C56: 屯田 | D56: 汉 | E56: 普通 | F56: 策略牌 | G56: — | H56: — | I56: 3 | J56: 0 | Q56: 为一座己方建筑回复5点HP；抽取1张牌 | R56: 募民徙塞下，皆便田作。 | S56: 《汉书·晁错传》(化用) | T56: 3 | U56: =ROUND((3-$I56/8)*$I56+2*$J56/3-1,3) -> 6.875 | V56: =IF($F56="策略牌",$I56,ROUND(VLOOKUP($G56,$A$6:$C$9,2,FALSE)*N($L56)+VLOOKUP($G56,$A$6:$C$9,3,FALSE)*N($M56)+$T56,3)) -> 3 | W56: =ROUND($V56-$U56,3) -> -3.875
A57: 9 | B57: han_009 | C57: 轻车骑 | D57: 汉 | E57: 稀有 | F57: 兵牌 | G57: 骑兵 | H57: 轻 | I57: 3 | J57: 1 | K57: 2 | L57: 3 | M57: 4 | N57: 1 | O57: 闪击,伏兵 | P57: Blitz,Ambush | R57: 轻车锐骑，昼夜兼行。 | S57: 《汉书·卫青传》(化用) | T57: 0.5 | U57: =ROUND((3-$I57/8)*$I57+2*$J57/3-1,3) -> 7.542 | V57: =IF($F57="策略牌",$I57,ROUND(VLOOKUP($G57,$A$6:$C$9,2,FALSE)*N($L57)+VLOOKUP($G57,$A$6:$C$9,3,FALSE)*N($M57)+$T57,3)) -> 7.6 | W57: =ROUND($V57-$U57,3) -> 0.058
A58: 10 | B58: han_010 | C58: 材官蹶张 | D58: 汉 | E58: 稀有 | F58: 兵牌 | G58: 弓兵 | H58: 中 | I58: 3 | J58: 1 | K58: 1 | L58: 4 | M58: 3 | N58: 2 | R58: 材官蹶张，弓弩并发。 | S58: 《汉书·申屠嘉传》(化用) | T58: 0 | U58: =ROUND((3-$I58/8)*$I58+2*$J58/3-1,3) -> 7.542 | V58: =IF($F58="策略牌",$I58,ROUND(VLOOKUP($G58,$A$6:$C$9,2,FALSE)*N($L58)+VLOOKUP($G58,$A$6:$C$9,3,FALSE)*N($M58)+$T58,3)) -> 7.2 | W58: =ROUND($V58-$U58,3) -> -0.342
A59: 11 | B59: han_011 | C59: 屯田卒 | D59: 汉 | E59: 稀有 | F59: 兵牌 | G59: 步兵 | H59: 中 | I59: 3 | J59: 1 | K59: 1 | L59: 4 | M59: 2 | N59: 1 | O59: 守护 | P59: Guard | R59: 且耕且守，边备以充。 | S59: 《汉书·赵充国传》(化用) | T59: 1 | U59: =ROUND((3-$I59/8)*$I59+2*$J59/3-1,3) -> 7.542 | V59: =IF($F59="策略牌",$I59,ROUND(VLOOKUP($G59,$A$6:$C$9,2,FALSE)*N($L59)+VLOOKUP($G59,$A$6:$C$9,3,FALSE)*N($M59)+$T59,3)) -> 7.2 | W59: =ROUND($V59-$U59,3) -> -0.342
A60: 12 | B60: han_012 | C60: 玄甲校士 | D60: 汉 | E60: 稀有 | F60: 兵牌 | G60: 步兵 | H60: 重 | I60: 4 | J60: 2 | K60: 1 | L60: 5 | M60: 4 | N60: 1 | O60: 重甲1 | P60: HeavyArmor | R60: 玄甲曜日，望之如墨。 | S60: 《汉书》(化用) | T60: 1 | U60: =ROUND((3-$I60/8)*$I60+2*$J60/3-1,3) -> 10.333 | V60: =IF($F60="策略牌",$I60,ROUND(VLOOKUP($G60,$A$6:$C$9,2,FALSE)*N($L60)+VLOOKUP($G60,$A$6:$C$9,3,FALSE)*N($M60)+$T60,3)) -> 10.1 | W60: =ROUND($V60-$U60,3) -> -0.233
A61: 13 | B61: han_013 | C61: 死士营 | D61: 汉 | E61: 稀有 | F61: 兵牌 | G61: 步兵 | H61: 中 | I61: 4 | J61: 1 | K61: 1 | L61: 4 | M61: 4 | N61: 1 | O61: 血战 | P61: BloodBattle | R61: 陷阵之志，有死无生。 | S61: 《后汉书·耿弇传》(化用) | T61: 1.5 | U61: =ROUND((3-$I61/8)*$I61+2*$J61/3-1,3) -> 9.667 | V61: =IF($F61="策略牌",$I61,ROUND(VLOOKUP($G61,$A$6:$C$9,2,FALSE)*N($L61)+VLOOKUP($G61,$A$6:$C$9,3,FALSE)*N($M61)+$T61,3)) -> 9.5 | W61: =ROUND($V61-$U61,3) -> -0.167
A62: 14 | B62: han_014 | C62: 骁骑 | D62: 汉 | E62: 稀有 | F62: 兵牌 | G62: 骑兵 | H62: 轻 | I62: 4 | J62: 1 | K62: 2 | L62: 5 | M62: 5 | N62: 1 | O62: 闪击 | P62: Blitz | R62: 骁骑十万，旌旗蔽野。 | S62: 《汉书·匈奴传》(化用) | T62: 0 | U62: =ROUND((3-$I62/8)*$I62+2*$J62/3-1,3) -> 9.667 | V62: =IF($F62="策略牌",$I62,ROUND(VLOOKUP($G62,$A$6:$C$9,2,FALSE)*N($L62)+VLOOKUP($G62,$A$6:$C$9,3,FALSE)*N($M62)+$T62,3)) -> 10 | W62: =ROUND($V62-$U62,3) -> 0.333
...

Sheet 基准表外条目
A1: 基准表外条目登记（只报告，不写入《基础公式》）
A2: 规则：两个卡池只允许使用《基础公式》B26:D64 里登记过的词条与效果。本表登记「曾经出现在旧表里、但基准表查不到」的条目，以及基准表自身留白/自相矛盾、需要你拍板的地方。任何基准表改动都等你确认后另行落表。
A4: 一、已从卡池中拆除的表外条目
A5: 序号 | B5: 条目 | C5: 原用法 | D5: 为什么不能用 / 基准表状态 | E5: 现在的替代方案（已落表）
A6: 1 | B6: 誓师 | C6: 支援(器械)部署增益｜部署当回合，己方所有已部署单位本回合 ATK+1 | D6: 基础表无「誓师」这一条；支援/器械类目前只有 buff 类费率可用 | E6: 本次两表都没有支援(器械)卡，所以这个形态暂时用不到；若你想保留「全军增益」，需要先定义「群体 buff 每点多少钱」——基础表只给了单体每点费率。
A7: 2 | B7: 临时ATK+3 | C7: buff·单体加攻｜指定一个友方单位本回合 ATK+3 | D7: 基础表 B50 已给费率（每点 0.75 费），但旧表把它当成一个固定价词条写进了 keywords 列 | E7: 已改为效果栏写法，费率照 B50，不再占词条列。
A8: 3 | B8: 临时HP+3 | C8: buff·单体加血｜为一个友方单位本回合 HP+3 | D8: 同上，B51 费率「每点 hp 记 0.5 费」 | E8: 本次未使用；若需要，直接按 0.5/点写进效果栏即可。
A9: 4 | B9: 指定直伤5 | C9: 直伤·指定5点｜对一名敌方兵牌造成5点伤害 | D9: B60 只有「指定3点=2」一个锚点，5 点档没有基准价；旧表按 1点=1 外推成 4.0，属表外取值 | E9: 已撤掉：秦·绝粮道 改为「指定3点伤害(2.0) + 压制(1.0)」= 3 费，两个分量都在基础表里有价，正好等于费用。
A10: 5 | B10: 整排伤害3 | C10: 直伤·整排3点｜对指定一排所有单位造成3点伤害 | D10: B64 只有「整排2点=3」一个锚点，3 点档属外推（旧表取 5.0） | E10: 已撤掉：汉·决水灌城 改为「指定3点伤害(2.0) + 随机3点伤害(1.0)」= 3 费，两个分量都有基准价。
A11: 6 | B11: 攻击后大营回血2 | C11: 加血类·兵种卡｜攻击后，为大营回复2hp | D11: B41 确实有这一条（1.5 费），但它写在「加血类」里、备注明写「仅限兵种卡」，是兵牌的效果而不是可挂载词条 | E11: 已撤掉词条写法：汉·屯田卒 改为带「守护」的 3 费 4/2 中甲步兵（|差值| 0.292）。若你想让这张卡走「攻击后回血」路线，我按 B41 = 1.5 费重新配面板即可。
A12: 7 | B12: 重甲3 | C12: 重甲第三层｜每层重甲在受到伤害时减少一点（三层） | D12: B44 有这一条（4.0 费） | E12: 基准价有、但本次没用上：5 费重型步兵的预算 12.208，带重甲3 需要面板降到约 3/3 才配得上，攻防比失衡（脚本会剔除）。→ 汉·虎贲营 改用 4/5 + 守护 + 重甲2（12.133，差值 −0.075），既保留「重甲营」的定位，也和 秦·锐士营（5/5 守护+重甲1）、汉·玄甲校士（4 费 重甲1）、汉·羽林壁垒（6 费 守护+重甲2）拉开档位。重甲3 留给后续朝代的 6 费以上重型单位。
A13: 8 | B13: 反制 | C13: 埋伏型解场牌（陷阱）｜（基础表 B45 只写了「满足触发条件时自动使用，不可主动使用，不消耗费用，起解场作用」，既没有触发条件也没有具体效果，等价费用一栏为空） | D13: 定位已明确：反制是一类**陷阱/埋伏牌**——不能主动打出，只在触发条件满足时自动发动，不消耗费用，作用是在对方攻势落点上做一次突袭式解场（出奇制胜）。基准表里仍缺「触发条件」与「触发后效果」两项，因此无法定价，本次两表未使用。 | E13: 设计意图已记录，**暂不需要定价**。已确认的示例：「对方攻击己方大营的第一个单位，攻击后立即死亡」——触发条件 = 敌方单位攻击己方大营；触发效果 = 该攻击者攻击后立即死亡（等价于一次定向消灭）。将来若要落表，需要补：①触发条件的枚举（如：敌方攻击己方大营 / 敌方部署 ≥N 费单位 / 己方单位被消灭时）；②触发效果的基准锚点（本例「攻击后立即死亡」可参照 B63「消灭一个敌方随机单位」= 6 费，但因为是条件触发、不可主动选择时机，实际等价费用应低于 6；具体档位由你定，我不擅自填）。
A15: 二、基准表里「有锚点但本次没用上」的档位（可能对后续朝代有用）
A16: 序号 | B16: 条目 | C16: 基准价 | D16: 基准表位置 | E16: 说明
A17: 1 | B17: 摸牌1 / 摸牌2 / 摸牌3 | C17: 1 / 3 / 6 | D17: B32:B34 | E17: 抽牌档。本次只用到 摸牌1（汉·屯田、汉·离间）和 摸牌3（秦·移民实边）；摸牌2 未使用
A18: 2 | B18: 建筑回血3 | C18: 1 | D18: B37 | E18: 本次只用到 建筑回血5（汉·屯田、汉·盐铁论）与 建筑回血7（秦·商君变法）
A19: 3 | B19: 兵回血3 | C19: 2 | D19: B40 | E19: 本次用到：秦·输粟（为友方单位回3血）、汉·盐铁论
A20: 4 | B20: 攻击后大营回血2 | C20: 1.5 | D20: B41 | E20: 仅限兵种卡。本次未使用（屯田卒 改走守护路线）
A21: 5 | B21: 重甲3 | C21: 4.0 | D21: B44 | E21: 见上表：5 费重型步兵预算容纳不下，留给后续朝代的 6 费以上重型单位
A22: 6 | B22: 抵抗 | C22: 0.5 | D22: B49 | E22: 免疫压制。本次兵牌未携带（重甲3 未使用，所以连带未出现）
A23: 7 | B23: 等价·ATK对齐HP | C23: 3 | D23: B53 | E23: 固定 3 费策略卡。本次未使用
A24: 8 | B24: 等价·敌HP调1 | C24: 2 | D24: B54 | E24: 固定 2 费策略卡。本次未使用
A25: 9 | B25: 等价·敌ATK调1 | C25: 2 | D25: B55 | E25: 固定 2 费策略卡。本次未使用
A26: 10 | B26: 召唤(牌堆) | C26: 0.5 | D26: B35 | E26: 词条。本次用到：汉·汉家大黄弩（部署时添加一张卡牌进入牌堆）
A27: 11 | B27: 召唤(手牌) | C27: 1 | D27: B36 | E27: 部署时从牌堆取一张入手。本次未使用
A28: 12 | B28: 消灭随机单位 | C28: 6 | D28: B63 | E28: 消灭一个敌方随机单位。本次未使用（6 费策略卡位被 秦·移民实边 的抽3张占用）
A29: 13 | B29: 整排伤害2 | C29: 3 | D29: B64 | E29: 本次用到：汉·飞石
A31: 三、基准表内部留白与冲突（只报告，未修改任何基准表单元格）
A32: · 反制（B45）：有名字、有效果描述、无触发条件、等价费用一栏为空 —— 基础表里唯一无法计价的条目。定位已明确为「埋伏型解场牌／陷阱」（不可主动使用、触发即发动、不耗费用、出奇制胜），已记录的示例是「对方攻击己方大营的第一个单位，攻击后立即死亡」。仍缺「触发条件」与「触发后效果」两项，故无法定价、暂不落表；若将来补档，档位由你定，脚本不擅自填价。
A33: · 守护部署加成：B29 备注写「部署时+1hp」，策划案 §4.3 写 +3HP。→ 本次按你确认取 +1HP（卡面 HP 已含）。
A34: · 血战等价费用：B30 = 1.5，策划案 §4.3 写 2.0。→ 本次按你确认取 1.5。
A35: · 闪击适用范围：B27 备注「骑兵类携带时等价为0，未携带算入-0.5」，没写步/弓/器怎么办。→ 本次按你确认：只对骑兵适用，步/弓/器不受影响。
A36: · 直伤类（B60~B64）：「指定3点=2」「随机3点=1」「整排2点=3」「消灭随机=6」四个档位彼此不成线性，1/2/4/5/7 点与整排 3 点都无锚点，因此这些档位本次一律不用。
A37: · 弃牌类（B56）：弃 1 张手牌固定 2 费，单独无法撑满 2 费以上的策略卡，因此必然要搭配第二个效果使用（秦·军功爵、汉·离间 都是「弃牌 + 另一效果」）。
A38: · buff 类（B50~B52）只给了「每点」费率，没有给「群体增益」的费率上限；备注只限定「仅限策略卡和支援卡的部署效果，增加数值的费用不得超过 3 费」。→ 本次全部按单点费率计价，单张 buff 费用最高 2.0 费（汉·破敌封赏 HP+4、秦·军功爵 ATK+2），未触 3 费上限。
A39: · ★支援(器械)类：已按你更新后的系数（E12:F12 = 1/1）重做。旧系数 2/2 时 3 费器械「面板+最小效果」最低 8.5，而门槛上限是 8.558 —— 只剩 0.25 余量、比基础表最小的效果价 0.5 还小，支援卡根本无法成立；改成 1/1 后预算与面板同量纲，3 费 3/4 +「本回合HP+3」（B51 每点 hp 记 0.5 费 = 1.5 费）正好落在预算上（8.5 vs 8.208，差值 +0.292）。秦·连弩台、汉·治粟都尉 即此配置。注意：支援(器械)现按 2 次行动计（与骑兵同级——器械架设后可连续输出）。
A40: · 费用曲线：策略牌的「效果价 = 费用」是硬约束，而基础表的效果价档位只有 0.5 / 1 / 1.5 / 2 / 2.5 / 3 / 4 / 6，因此不是每个费用点都能配出策略卡（5 费只有「整排2点(3) + 兵回血3(2)」一类组合，6 费只有「摸牌3」「消灭随机」）。1 费档本次用「随机直伤3（B61 = 1 费）」做成了 秦·弩矢督 与 汉·招降。
A41: · B47~B59 之间有留白行（47/57/58/59 附近的空行），未来若补新条目，补进去后本脚本会自动可用（改 ENTRY / EFFECT_TEXT 即可）。
